<?xml version="1.0" encoding="utf-8"?>
<!-- This URDF was automatically created by SolidWorks to URDF Exporter! Originally created by Stephen Brawner (brawner@gmail.com) 
     Commit Version: 1.6.0-1-g15f4949  Build Version: 1.6.7594.29634
     For more information, please see http://wiki.ros.org/sw_urdf_exporter -->
<robot
  name="Car_1">
  <link
    name="base_link">
    <inertial>
      <origin
        xyz="-0.051941384919569 2.87161683638156E-18 0.0176351053030645"
        rpy="0 0 0" />
      <mass
        value="0.608379807117841" />
      <inertia
        ixx="0.00270780161093748"
        ixy="1.83523696969695E-18"
        ixz="-0.000466901162534425"
        iyy="0.0036443624416039"
        iyz="9.43451341696599E-19"
        izz="0.0052251348540921" />
    </inertial>
    <visual>
      <origin
        xyz="0 0 0"
        rpy="0 0 0" />
      <geometry>
        <mesh
          filename="package://Car_1/meshes/base_link.STL" />
      </geometry>
      <material
        name="">
        <color
          rgba="0.752941176470588 0.752941176470588 0.752941176470588 1" />
      </material>
    </visual>
    <collision>
      <origin
        xyz="0 0 0"
        rpy="0 0 0" />
      <geometry>
        <mesh
          filename="package://Car_1/meshes/base_link.STL" />
      </geometry>
    </collision>
  </link>
  <link
    name="lwheel_link">
    <inertial>
      <origin
        xyz="2.77555756156289E-17 -0.00295821946504571 3.46944695195361E-18"
        rpy="0 0 0" />
      <mass
        value="0.0203132942311367" />
      <inertia
        ixx="7.33043982917312E-06"
        ixy="-1.0014250588411E-21"
        ixz="7.2781884837501E-21"
        iyy="1.39291601103077E-05"
        iyz="6.71684802553164E-22"
        izz="7.33043982917311E-06" />
    </inertial>
    <visual>
      <origin
        xyz="0 0 0"
        rpy="0 0 0" />
      <geometry>
        <mesh
          filename="package://Car_1/meshes/lwheel_link.STL" />
      </geometry>
      <material
        name="">
        <color
          rgba="0.752941176470588 0.752941176470588 0.752941176470588 1" />
      </material>
    </visual>
    <collision>
      <origin
        xyz="0 0 0"
        rpy="0 0 0" />
      <geometry>
        <mesh
          filename="package://Car_1/meshes/lwheel_link.STL" />
      </geometry>
    </collision>
  </link>
  <joint
    name="lwheel_joint"
    type="continuous">
    <origin
      xyz="-0.11 0.1395 0.026"
      rpy="0 0 0" />
    <parent
      link="base_link" />
    <child
      link="lwheel_link" />
    <axis
      xyz="0 -1 0" />
  </joint>
  <link
    name="rwheel_link">
    <inertial>
      <origin
        xyz="2.77555756156289E-17 -0.00295821946504568 1.04083408558608E-17"
        rpy="0 0 0" />
      <mass
        value="0.0203132942311367" />
      <inertia
        ixx="7.33043982917312E-06"
        ixy="8.68041222761222E-22"
        ixz="7.29278556594031E-21"
        iyy="1.39291601103077E-05"
        iyz="-8.14575690586412E-22"
        izz="7.33043982917312E-06" />
    </inertial>
    <visual>
      <origin
        xyz="0 0 0"
        rpy="0 0 0" />
      <geometry>
        <mesh
          filename="package://Car_1/meshes/rwheel_link.STL" />
      </geometry>
      <material
        name="">
        <color
          rgba="0.752941176470588 0.752941176470588 0.752941176470588 1" />
      </material>
    </visual>
    <collision>
      <origin
        xyz="0 0 0"
        rpy="0 0 0" />
      <geometry>
        <mesh
          filename="package://Car_1/meshes/rwheel_link.STL" />
      </geometry>
    </collision>
  </link>
  <joint
    name="rwheel_joint"
    type="continuous">
    <origin
      xyz="-0.11 -0.1395 0.026"
      rpy="3.14159265358979 0 0" />
    <parent
      link="base_link" />
    <child
      link="rwheel_link" />
    <axis
      xyz="0 -1 0" />
  </joint>
</robot>